Workbook
Name UPDATE: 'Data Sheet'!$E$1

Sheet Profit & Loss
A1: ='Data Sheet'!B1 -> HINDUSTAN UNILEVER LTD | H1: =UPDATE | M1: SCREENER.IN
A3: Narration | B3: ='Data Sheet'!B16 -> 42825 | C3: ='Data Sheet'!C16 -> 43190 | D3: ='Data Sheet'!D16 -> 43555 | E3: ='Data Sheet'!E16 -> 43921 | F3: ='Data Sheet'!F16 -> 44286 | G3: ='Data Sheet'!G16 -> 44651 | H3: ='Data Sheet'!H16 -> 45016 | I3: ='Data Sheet'!I16 -> 45382 | ... K3: ='Data Sheet'!K16 -> 46112 | L3: Trailing | M3: Best Case | N3: Worst Case
A4: Sales | B4: ='Data Sheet'!B17 -> 33162 | C4: ='Data Sheet'!C17 -> 35545 | D4: ='Data Sheet'!D17 -> 39310 | E4: ='Data Sheet'!E17 -> 39783 | F4: ='Data Sheet'!F17 -> 47028 | G4: ='Data Sheet'!G17 -> 52446 | H4: ='Data Sheet'!H17 -> 60580 | I4: ='Data Sheet'!I17 -> 61896 | ... K4: ='Data Sheet'!K17 -> 64468 | L4: =SUM(Quarters!H4:K4) -> 66052 | M4: =$K4+M23*K4 -> 67768.768 | N4: =$K4+N23*L4 -> 65851.867
A5: Expenses | B5: =SUM('Data Sheet'!B18,'Data Sheet'!B20:B24, -1*'Data Sheet'!B19) -> 26834 | C5: =SUM('Data Sheet'!C18,'Data Sheet'!C20:C24, -1*'Data Sheet'!C19) -> 28046 | D5: =SUM('Data Sheet'!D18,'Data Sheet'!D20:D24, -1*'Data Sheet'!D19) -> 30430 | E5: =SUM('Data Sheet'!E18,'Data Sheet'!E20:E24, -1*'Data Sheet'!E19) -> 29922 | F5: =SUM('Data Sheet'!F18,'Data Sheet'!F20:F24, -1*'Data Sheet'!F19) -> 35402 | G5: =SUM('Data Sheet'!G18,'Data Sheet'!G20:G24, -1*'Data Sheet'!G19) -> 39589 | H5: =SUM('Data Sheet'!H18,'Data Sheet'!H20:H24, -1*'Data Sheet'!H19) -> 46433 | I5: =SUM('Data Sheet'!I18,'Data Sheet'!I20:I24, -1*'Data Sheet'!I19) -> 47237 | ... K5: =SUM('Data Sheet'!K18,'Data Sheet'!K20:K24, -1*'Data Sheet'!K19) -> 49429 | L5: =SUM(Quarters!H5:K5) -> 50705 | M5: =M4-M6 -> 51738.984 | N5: =N4-N6 -> 50551.368
A6: Operating Profit | B6: =B4-B5 -> 6328 | C6: =C4-C5 -> 7499 | D6: =D4-D5 -> 8880 | E6: =E4-E5 -> 9861 | F6: =F4-F5 -> 11626 | G6: =G4-G5 -> 12857 | H6: =H4-H5 -> 14147 | I6: =I4-I5 -> 14659 | ... K6: =K4-K5 -> 15039 | L6: =SUM(Quarters!H6:K6) -> 15347 | M6: =M4*M24 -> 16029.784 | N6: =N4*N24 -> 15300.5
A7: Other Income | B7: ='Data Sheet'!B25 -> 606 | C7: ='Data Sheet'!C25 -> 353 | D7: ='Data Sheet'!D25 -> 322 | E7: ='Data Sheet'!E25 -> 424 | F7: ='Data Sheet'!F25 -> 170 | G7: ='Data Sheet'!G25 -> 219 | H7: ='Data Sheet'!H25 -> 448 | I7: ='Data Sheet'!I25 -> 817 | ... K7: ='Data Sheet'!K25 -> 4923 | L7: =SUM(Quarters!H7:K7) -> 4933 | M7: 0 | N7: 0
A8: Depreciation | B8: ='Data Sheet'!B26 -> 432 | C8: ='Data Sheet'!C26 -> 520 | D8: ='Data Sheet'!D26 -> 565 | E8: ='Data Sheet'!E26 -> 1002 | F8: ='Data Sheet'!F26 -> 1074 | G8: ='Data Sheet'!G26 -> 1091 | H8: ='Data Sheet'!H26 -> 1137 | I8: ='Data Sheet'!I26 -> 1216 | ... K8: ='Data Sheet'!K26 -> 1333 | L8: =SUM(Quarters!H8:K8) -> 1360 | M8: =+$L8 -> 1360 | N8: =+$L8 -> 1360
A9: Interest | B9: ='Data Sheet'!B27 -> 35 | C9: ='Data Sheet'!C27 -> 26 | D9: ='Data Sheet'!D27 -> 33 | E9: ='Data Sheet'!E27 -> 118 | F9: ='Data Sheet'!F27 -> 117 | G9: ='Data Sheet'!G27 -> 106 | H9: ='Data Sheet'!H27 -> 114 | I9: ='Data Sheet'!I27 -> 334 | ... K9: ='Data Sheet'!K27 -> 410 | L9: =SUM(Quarters!H9:K9) -> 363 | M9: =+$L9 -> 363 | N9: =+$L9 -> 363
A10: Profit before tax | B10: ='Data Sheet'!B28 -> 6467 | C10: ='Data Sheet'!C28 -> 7306 | D10: ='Data Sheet'!D28 -> 8604 | E10: ='Data Sheet'!E28 -> 9165 | F10: ='Data Sheet'!F28 -> 10605 | G10: ='Data Sheet'!G28 -> 11879 | H10: ='Data Sheet'!H28 -> 13344 | I10: ='Data Sheet'!I28 -> 13926 | ... K10: ='Data Sheet'!K28 -> 18219 | L10: =SUM(Quarters!H10:K10) -> 18557 | M10: =M6+M7-SUM(M8:M9) -> 14306.784 | N10: =N6+N7-SUM(N8:N9) -> 13577.5
A11: Tax | B11: ='Data Sheet'!B29 -> 1977 | C11: ='Data Sheet'!C29 -> 2079 | D11: ='Data Sheet'!D29 -> 2544 | E11: ='Data Sheet'!E29 -> 2409 | F11: ='Data Sheet'!F29 -> 2606 | G11: ='Data Sheet'!G29 -> 2987 | H11: ='Data Sheet'!H29 -> 3201 | I11: ='Data Sheet'!I29 -> 3644 | ... K11: ='Data Sheet'!K29 -> 3160 | L11: =SUM(Quarters!H11:K11) -> 3586 | M11: =IF($L10>0,$L11/$L10,0) -> 0.19324244 | N11: =IF($L10>0,$L11/$L10,0) -> 0.19324244
A12: Net profit | B12: ='Data Sheet'!B30 -> 4476 | C12: ='Data Sheet'!C30 -> 5214 | D12: ='Data Sheet'!D30 -> 6054 | E12: ='Data Sheet'!E30 -> 6748 | F12: ='Data Sheet'!F30 -> 7995 | G12: ='Data Sheet'!G30 -> 8879 | H12: ='Data Sheet'!H30 -> 10120 | I12: ='Data Sheet'!I30 -> 10277 | ... K12: ='Data Sheet'!K30 -> 15040 | L12: =SUM(Quarters!H12:K12) -> 14957 | M12: =M10-M11*M10 -> 11542.106 | N12: =N10-N11*N10 -> 10953.751
A13: EPS | B13: =IF('Data Sheet'!B93>0,B12/'Data Sheet'!B93,0) -> 20.681052 | C13: =IF('Data Sheet'!C93>0,C12/'Data Sheet'!C93,0) -> 24.088704 | D13: =IF('Data Sheet'!D93>0,D12/'Data Sheet'!D93,0) -> 27.966924 | E13: =IF('Data Sheet'!E93>0,E12/'Data Sheet'!E93,0) -> 31.171471 | F13: =IF('Data Sheet'!F93>0,F12/'Data Sheet'!F93,0) -> 34.027068 | G13: =IF('Data Sheet'!G93>0,G12/'Data Sheet'!G93,0) -> 37.789411 | H13: =IF('Data Sheet'!H93>0,H12/'Data Sheet'!H93,0) -> 43.071161 | I13: =IF('Data Sheet'!I93>0,I12/'Data Sheet'!I93,0) -> 43.73936 | ... K13: =IF('Data Sheet'!K93>0,K12/'Data Sheet'!K93,0) -> 64.010895 | L13: =IF('Data Sheet'!$B6>0,'Profit & Loss'!L12/'Data Sheet'!$B6,0) -> 63.657879 | M13: =IF('Data Sheet'!$B6>0,'Profit & Loss'!M12/'Data Sheet'!$B6,0) -> 49.123889 | N13: =IF('Data Sheet'!$B6>0,'Profit & Loss'!N12/'Data Sheet'!$B6,0) -> 46.619812
A14: Price to earning | B14: =IF(B15>0,B15/B13,"") -> 42.193696 | C14: =IF(C15>0,C15/C13,"") -> 52.975453 | D14: =IF(D15>0,D15/D13,"") -> 58.409356 | E14: =IF(E15>0,E15/E13,"") -> 70.571903 | F14: =IF(F15>0,F15/F13,"") -> 68.390258 | G14: =IF(G15>0,G15/G13,"") -> 51.884905 | H14: =IF(H15>0,H15/H13,"") -> 56.892824 | I14: =IF(I15>0,I15/I13,"") -> 49.546678 | ... K14: =IF(K15>0,K15/K13,"") -> 32.107034 | L14: =IF(L13>0,L15/L13,0) -> 30.473054 | M14: =M25 -> 39.956645 | N14: =N25 -> 30.473054
A15: Price | B15: ='Data Sheet'!B90 -> 872.61 | C15: ='Data Sheet'!C90 -> 1276.11 | D15: ='Data Sheet'!D90 -> 1633.53 | E15: ='Data Sheet'!E90 -> 2199.83 | F15: ='Data Sheet'!F90 -> 2327.12 | G15: ='Data Sheet'!G90 -> 1960.7 | H15: ='Data Sheet'!H90 -> 2450.44 | I15: ='Data Sheet'!I90 -> 2167.14 | ... K15: ='Data Sheet'!K90 -> 2055.2 | L15: ='Data Sheet'!B8 -> 1939.85 | M15: =M13*M14 -> 1962.8258 | N15: =N13*N14 -> 1420.6481
A17: RATIOS:
A18: Dividend Payout | B18: =IF('Data Sheet'!B30>0, 'Data Sheet'!B31/'Data Sheet'!B30, 0) -> 0.82037534 | C18: =IF('Data Sheet'!C30>0, 'Data Sheet'!C31/'Data Sheet'!C30, 0) -> 0.82853855 | D18: =IF('Data Sheet'!D30>0, 'Data Sheet'!D31/'Data Sheet'!D30, 0) -> 0.78493558 | E18: =IF('Data Sheet'!E30>0, 'Data Sheet'!E31/'Data Sheet'!E30, 0) -> 0.80023711 | F18: =IF('Data Sheet'!F30>0, 'Data Sheet'!F31/'Data Sheet'!F30, 0) -> 1.1904315 | G18: =IF('Data Sheet'!G30>0, 'Data Sheet'!G31/'Data Sheet'!G30, 0) -> 0.89987611 | H18: =IF('Data Sheet'!H30>0, 'Data Sheet'!H31/'Data Sheet'!H30, 0) -> 0.90563241 | I18: =IF('Data Sheet'!I30>0, 'Data Sheet'!I31/'Data Sheet'!I30, 0) -> 0.960397 | ... K18: =IF('Data Sheet'!K30>0, 'Data Sheet'!K31/'Data Sheet'!K30, 0) -> 0.640625
A19: OPM | B19: =IF(B6>0,B6/B4,0) -> 0.19082082 | C19: =IF(C6>0,C6/C4,0) -> 0.21097201 | D19: =IF(D6>0,D6/D4,0) -> 0.22589672 | E19: =IF(E6>0,E6/E4,0) -> 0.24786969 | F19: =IF(F6>0,F6/F4,0) -> 0.24721443 | G19: =IF(G6>0,G6/G4,0) -> 0.24514739 | H19: =IF(H6>0,H6/H4,0) -> 0.23352592 | I19: =IF(I6>0,I6/I4,0) -> 0.23683275 | ... L19: =IF(L6>0,L6/L4,0) -> 0.23234724
G22: TRENDS: | H22: 10 YEARS | I22: 7 YEARS | J22: 5 YEARS | K22: 3 YEARS | L22: RECENT | M22: BEST | N22: WORST
G23: Sales Growth | H23: =IF(B4=0,"",POWER($K4/B4,1/9)-1) -> 0.076658974 | I23: =IF(D4=0,"",POWER($K4/D4,1/7)-1) -> 0.073227008 | J23: =IF(F4=0,"",POWER($K4/F4,1/5)-1) -> 0.065117542 | K23: =IF(H4=0,"",POWER($K4/H4, 1/3)-1) -> 0.020951182 | L23: =IF(ISERROR(MAX(IF(J4=0,"",(K4-J4)/J4),IF(K4=0,"",(L4-K4)/K4))),"",MAX(IF(J4=0,"",(K4-J4)/J4),IF(K4=0,"",(L4-K4)/K4))) -> 0.051200104 | M23: =MAX(K23:L23) -> 0.051200104 | N23: =MIN(H23:L23) -> 0.020951182
G24: OPM | H24: =IF(SUM(B4:$K$4)=0,"",SUMPRODUCT(B19:$K$19,B4:$K$4)/SUM(B4:$K$4)) -> 0.23326593 | I24: =IF(SUM(E4:$K$4)=0,"",SUMPRODUCT(E19:$K$19,E4:$K$4)/SUM(E4:$K$4)) -> 0.23969045 | J24: =IF(SUM(G4:$K$4)=0,"",SUMPRODUCT(G19:$K$19,G4:$K$4)/SUM(G4:$K$4)) -> 0.23743175 | K24: =IF(SUM(I4:$K$4)=0, "", SUMPRODUCT(I19:$K$19,I4:$K$4)/SUM(I4:$K$4)) -> 0.23653645 | L24: =L19 -> 0.23234724 | M24: =MAX(K24:L24) -> 0.23653645 | N24: =MIN(H24:L24) -> 0.23234724
G25: Price to Earning | H25: =IF(ISERROR(AVERAGEIF(B14:$L14,">0")),"",AVERAGEIF(B14:$L14,">0")) -> 51.01318 | I25: =IF(ISERROR(AVERAGEIF(E14:$L14,">0")),"",AVERAGEIF(E14:$L14,">0")) -> 50.945809 | J25: =IF(ISERROR(AVERAGEIF(G14:$L14,">0")),"",AVERAGEIF(G14:$L14,">0")) -> 44.767385 | K25: =IF(ISERROR(AVERAGEIF(I14:$L14,">0")),"",AVERAGEIF(I14:$L14,">0")) -> 39.956645 | L25: =L14 -> 30.473054 | M25: =MAX(K25:L25) -> 39.956645 | N25: =MIN(H25:L25) -> 30.473054

Sheet Balance Sheet
A1: ='Profit & Loss'!A1 -> HINDUSTAN UNILEVER LTD | E1: =UPDATE | J1: SCREENER.IN
A3: Narration | B3: ='Data Sheet'!B56 -> 42825 | C3: ='Data Sheet'!C56 -> 43190 | D3: ='Data Sheet'!D56 -> 43555 | E3: ='Data Sheet'!E56 -> 43921 | F3: ='Data Sheet'!F56 -> 44286 | G3: ='Data Sheet'!G56 -> 44651 | H3: ='Data Sheet'!H56 -> 45016 | I3: ='Data Sheet'!I56 -> 45382 | ... K3: ='Data Sheet'!K56 -> 46112
A4: Equity Share Capital | B4: ='Data Sheet'!B57 -> 216 | C4: ='Data Sheet'!C57 -> 216 | D4: ='Data Sheet'!D57 -> 216 | E4: ='Data Sheet'!E57 -> 216 | F4: ='Data Sheet'!F57 -> 235 | G4: ='Data Sheet'!G57 -> 235 | H4: ='Data Sheet'!H57 -> 235 | I4: ='Data Sheet'!I57 -> 235 | ... K4: ='Data Sheet'!K57 -> 235
A5: Reserves | B5: ='Data Sheet'!B58 -> 6528 | C5: ='Data Sheet'!C58 -> 7065 | D5: ='Data Sheet'!D58 -> 7651 | E5: ='Data Sheet'!E58 -> 8013 | F5: ='Data Sheet'!F58 -> 47439 | G5: ='Data Sheet'!G58 -> 48826 | H5: ='Data Sheet'!H58 -> 50069 | I5: ='Data Sheet'!I58 -> 50983 | ... K5: ='Data Sheet'!K58 -> 48504
A6: Borrowings | B6: ='Data Sheet'!B59 -> 277 | C6: ='Data Sheet'!C59 -> 0 | D6: ='Data Sheet'!D59 -> 99 | E6: ='Data Sheet'!E59 -> 0 | F6: ='Data Sheet'!F59 -> 0 | G6: ='Data Sheet'!G59 -> 1043 | H6: ='Data Sheet'!H59 -> 1219 | I6: ='Data Sheet'!I59 -> 1484 | ... K6: ='Data Sheet'!K59 -> 1478
A7: Other Liabilities | B7: ='Data Sheet'!B60 -> 8685 | C7: ='Data Sheet'!C60 -> 10581 | D7: ='Data Sheet'!D60 -> 10663 | E7: ='Data Sheet'!E60 -> 11924 | F7: ='Data Sheet'!F60 -> 21066 | G7: ='Data Sheet'!G60 -> 20402 | H7: ='Data Sheet'!H60 -> 21554 | I7: ='Data Sheet'!I60 -> 25787 | ... K7: ='Data Sheet'!K60 -> 29521
A8: Total | B8: ='Data Sheet'!B61 -> 15706 | C8: ='Data Sheet'!C61 -> 17862 | D8: ='Data Sheet'!D61 -> 18629 | E8: ='Data Sheet'!E61 -> 20153 | F8: ='Data Sheet'!F61 -> 68740 | G8: ='Data Sheet'!G61 -> 70506 | H8: ='Data Sheet'!H61 -> 73077 | I8: ='Data Sheet'!I61 -> 78489 | ... K8: ='Data Sheet'!K61 -> 79738
A10: Net Block | B10: ='Data Sheet'!B62 -> 4419 | C10: ='Data Sheet'!C62 -> 4528 | D10: ='Data Sheet'!D62 -> 4715 | E10: ='Data Sheet'!E62 -> 5479 | F10: ='Data Sheet'!F62 -> 51443 | G10: ='Data Sheet'!G62 -> 51473 | H10: ='Data Sheet'!H62 -> 52678 | I10: ='Data Sheet'!I62 -> 53744 | ... K10: ='Data Sheet'!K62 -> 57428
A11: Capital Work in Progress | B11: ='Data Sheet'!B63 -> 229 | C11: ='Data Sheet'!C63 -> 461 | D11: ='Data Sheet'!D63 -> 406 | E11: ='Data Sheet'!E63 -> 597 | F11: ='Data Sheet'!F63 -> 745 | G11: ='Data Sheet'!G63 -> 1313 | H11: ='Data Sheet'!H63 -> 1132 | I11: ='Data Sheet'!I63 -> 1025 | ... K11: ='Data Sheet'!K63 -> 880
A12: Investments | B12: ='Data Sheet'!B64 -> 3794 | C12: ='Data Sheet'!C64 -> 2873 | D12: ='Data Sheet'!D64 -> 2716 | E12: ='Data Sheet'!E64 -> 1255 | F12: ='Data Sheet'!F64 -> 2709 | G12: ='Data Sheet'!G64 -> 3521 | H12: ='Data Sheet'!H64 -> 2882 | I12: ='Data Sheet'!I64 -> 4625 | ... K12: ='Data Sheet'!K64 -> 4359
A13: Other Assets | B13: ='Data Sheet'!B65 -> 7264 | C13: ='Data Sheet'!C65 -> 10000 | D13: ='Data Sheet'!D65 -> 10792 | E13: ='Data Sheet'!E65 -> 12822 | F13: ='Data Sheet'!F65 -> 13843 | G13: ='Data Sheet'!G65 -> 14199 | H13: ='Data Sheet'!H65 -> 16385 | I13: ='Data Sheet'!I65 -> 19095 | ... K13: ='Data Sheet'!K65 -> 17071
A14: Total | B14: ='Data Sheet'!B66 -> 15706 | C14: ='Data Sheet'!C66 -> 17862 | D14: ='Data Sheet'!D66 -> 18629 | E14: ='Data Sheet'!E66 -> 20153 | F14: ='Data Sheet'!F66 -> 68740 | G14: ='Data Sheet'!G66 -> 70506 | H14: ='Data Sheet'!H66 -> 73077 | I14: ='Data Sheet'!I66 -> 78489 | ... K14: ='Data Sheet'!K66 -> 79738
A16: Working Capital | B16: =B13-B7 -> -1421 | C16: =C13-C7 -> -581 | D16: =D13-D7 -> 129 | E16: =E13-E7 -> 898 | F16: =F13-F7 -> -7223 | G16: =G13-G7 -> -6203 | H16: =H13-H7 -> -5169 | I16: =I13-I7 -> -6692 | ... K16: =K13-K7 -> -12450
A17: Debtors | B17: ='Data Sheet'!B67 -> 1085 | C17: ='Data Sheet'!C67 -> 1310 | D17: ='Data Sheet'!D67 -> 1816 | E17: ='Data Sheet'!E67 -> 1149 | F17: ='Data Sheet'!F67 -> 1758 | G17: ='Data Sheet'!G67 -> 2236 | H17: ='Data Sheet'!H67 -> 3079 | I17: ='Data Sheet'!I67 -> 2997 | ... K17: ='Data Sheet'!K67 -> 3379
A18: Inventory | B18: ='Data Sheet'!B68 -> 2541 | C18: ='Data Sheet'!C68 -> 2513 | D18: ='Data Sheet'!D68 -> 2574 | E18: ='Data Sheet'!E68 -> 2767 | F18: ='Data Sheet'!F68 -> 3579 | G18: ='Data Sheet'!G68 -> 4096 | H18: ='Data Sheet'!H68 -> 4251 | I18: ='Data Sheet'!I68 -> 4022 | ... K18: ='Data Sheet'!K68 -> 4789
A20: Debtor Days | B20: =IF('Profit & Loss'!B4>0,'Balance Sheet'!B17/('Profit & Loss'!B4/365),0) -> 11.942133 | C20: =IF('Profit & Loss'!C4>0,'Balance Sheet'!C17/('Profit & Loss'!C4/365),0) -> 13.451962 | D20: =IF('Profit & Loss'!D4>0,'Balance Sheet'!D17/('Profit & Loss'!D4/365),0) -> 16.861867 | E20: =IF('Profit & Loss'!E4>0,'Balance Sheet'!E17/('Profit & Loss'!E4/365),0) -> 10.541814 | F20: =IF('Profit & Loss'!F4>0,'Balance Sheet'!F17/('Profit & Loss'!F4/365),0) -> 13.644425 | G20: =IF('Profit & Loss'!G4>0,'Balance Sheet'!G17/('Profit & Loss'!G4/365),0) -> 15.56153 | H20: =IF('Profit & Loss'!H4>0,'Balance Sheet'!H17/('Profit & Loss'!H4/365),0) -> 18.551255 | I20: =IF('Profit & Loss'!I4>0,'Balance Sheet'!I17/('Profit & Loss'!I4/365),0) -> 17.673275 | ... K20: =IF('Profit & Loss'!K4>0,'Balance Sheet'!K17/('Profit & Loss'!K4/365),0) -> 19.130964
A21: Inventory Turnover | B21: =IF('Balance Sheet'!B18>0,'Profit & Loss'!B4/'Balance Sheet'!B18,0) -> 13.050767 | C21: =IF('Balance Sheet'!C18>0,'Profit & Loss'!C4/'Balance Sheet'!C18,0) -> 14.144449 | D21: =IF('Balance Sheet'!D18>0,'Profit & Loss'!D4/'Balance Sheet'!D18,0) -> 15.27195 | E21: =IF('Balance Sheet'!E18>0,'Profit & Loss'!E4/'Balance Sheet'!E18,0) -> 14.377665 | F21: =IF('Balance Sheet'!F18>0,'Profit & Loss'!F4/'Balance Sheet'!F18,0) -> 13.139983 | G21: =IF('Balance Sheet'!G18>0,'Profit & Loss'!G4/'Balance Sheet'!G18,0) -> 12.804199 | H21: =IF('Balance Sheet'!H18>0,'Profit & Loss'!H4/'Balance Sheet'!H18,0) -> 14.250765 | I21: =IF('Balance Sheet'!I18>0,'Profit & Loss'!I4/'Balance Sheet'!I18,0) -> 15.389359 | ... K21: =IF('Balance Sheet'!K18>0,'Profit & Loss'!K4/'Balance Sheet'!K18,0) -> 13.461683
A23: Return on Equity | B23: =IF(SUM('Balance Sheet'!B4:B5)>0,'Profit & Loss'!B12/SUM('Balance Sheet'!B4:B5),"") -> 0.66370107 | C23: =IF(SUM('Balance Sheet'!C4:C5)>0,'Profit & Loss'!C12/SUM('Balance Sheet'!C4:C5),"") -> 0.71611042 | D23: =IF(SUM('Balance Sheet'!D4:D5)>0,'Profit & Loss'!D12/SUM('Balance Sheet'!D4:D5),"") -> 0.76954366 | E23: =IF(SUM('Balance Sheet'!E4:E5)>0,'Profit & Loss'!E12/SUM('Balance Sheet'!E4:E5),"") -> 0.82002673 | F23: =IF(SUM('Balance Sheet'!F4:F5)>0,'Profit & Loss'!F12/SUM('Balance Sheet'!F4:F5),"") -> 0.16770147 | G23: =IF(SUM('Balance Sheet'!G4:G5)>0,'Profit & Loss'!G12/SUM('Balance Sheet'!G4:G5),"") -> 0.18097878 | H23: =IF(SUM('Balance Sheet'!H4:H5)>0,'Profit & Loss'!H12/SUM('Balance Sheet'!H4:H5),"") -> 0.20117684 | I23: =IF(SUM('Balance Sheet'!I4:I5)>0,'Profit & Loss'!I12/SUM('Balance Sheet'!I4:I5),"") -> 0.20065211 | ... K23: =IF(SUM('Balance Sheet'!K4:K5)>0,'Profit & Loss'!K12/SUM('Balance Sheet'!K4:K5),"") -> 0.30858245
A24: Return on Capital Emp | C24: =IF((B4+B5+B6+C4+C5+C6)>0,('Profit & Loss'!C10+'Profit & Loss'!C9)*2/(B4+B5+B6+C4+C5+C6),"") -> 1.0253111 | D24: =IF((C4+C5+C6+D4+D5+D6)>0,('Profit & Loss'!D10+'Profit & Loss'!D9)*2/(C4+C5+C6+D4+D5+D6),"") -> 1.1329442 | E24: =IF((D4+D5+D6+E4+E5+E6)>0,('Profit & Loss'!E10+'Profit & Loss'!E9)*2/(D4+D5+D6+E4+E5+E6),"") -> 1.1464032 | F24: =IF((E4+E5+E6+F4+F5+F6)>0,('Profit & Loss'!F10+'Profit & Loss'!F9)*2/(E4+E5+E6+F4+F5+F6),"") -> 0.38359301 | G24: =IF((F4+F5+F6+G4+G5+G6)>0,('Profit & Loss'!G10+'Profit & Loss'!G9)*2/(F4+F5+F6+G4+G5+G6),"") -> 0.24514717 | H24: =IF((G4+G5+G6+H4+H5+H6)>0,('Profit & Loss'!H10+'Profit & Loss'!H9)*2/(G4+G5+G6+H4+H5+H6),"") -> 0.26485088 | I24: =IF((H4+H5+H6+I4+I5+I6)>0,('Profit & Loss'!I10+'Profit & Loss'!I9)*2/(H4+H5+H6+I4+I5+I6),"") -> 0.27363876 | J24: =IF((I4+I5+I6+J4+J5+J6)>0,('Profit & Loss'!J10+'Profit & Loss'!J9)*2/(I4+I5+I6+J4+J5+J6),"") -> 0.28529571 | K24: =IF((J4+J5+J6+K4+K5+K6)>0,('Profit & Loss'!K10+'Profit & Loss'!K9)*2/(J4+J5+J6+K4+K5+K6),"") -> 0.36791847

Sheet Cash Flow
A1: ='Balance Sheet'!A1 -> HINDUSTAN UNILEVER LTD | E1: =UPDATE | J1: SCREENER.IN
A3: Narration | B3: ='Data Sheet'!B81 -> 42825 | C3: ='Data Sheet'!C81 -> 43190 | D3: ='Data Sheet'!D81 -> 43555 | E3: ='Data Sheet'!E81 -> 43921 | F3: ='Data Sheet'!F81 -> 44286 | G3: ='Data Sheet'!G81 -> 44651 | H3: ='Data Sheet'!H81 -> 45016 | I3: ='Data Sheet'!I81 -> 45382 | ... K3: ='Data Sheet'!K81 -> 46112
A4: Cash from Operating Activity | B4: ='Data Sheet'!B82 -> 5185 | C4: ='Data Sheet'!C82 -> 6059 | D4: ='Data Sheet'!D82 -> 5800 | E4: ='Data Sheet'!E82 -> 7623 | F4: ='Data Sheet'!F82 -> 9163 | G4: ='Data Sheet'!G82 -> 9048 | H4: ='Data Sheet'!H82 -> 9991 | I4: ='Data Sheet'!I82 -> 15469 | ... K4: ='Data Sheet'!K82 -> 10999
A5: Cash from Investing Activity | B5: ='Data Sheet'!B83 -> -1173 | C5: ='Data Sheet'!C83 -> -1063 | D5: ='Data Sheet'!D83 -> -438 | E5: ='Data Sheet'!E83 -> 1791 | F5: ='Data Sheet'!F83 -> -1228 | G5: ='Data Sheet'!G83 -> -1728 | H5: ='Data Sheet'!H83 -> -1484 | I5: ='Data Sheet'!I83 -> -5324 | ... K5: ='Data Sheet'!K83 -> -3676
A6: Cash from Financing Activity | B6: ='Data Sheet'!B84 -> -4214 | C6: ='Data Sheet'!C84 -> -4975 | D6: ='Data Sheet'!D84 -> -5390 | E6: ='Data Sheet'!E84 -> -6819 | F6: ='Data Sheet'!F84 -> -9309 | G6: ='Data Sheet'!G84 -> -8015 | H6: ='Data Sheet'!H84 -> -8953 | I6: ='Data Sheet'!I84 -> -10034 | ... K6: ='Data Sheet'!K84 -> -10810
A7: Net Cash Flow | B7: ='Data Sheet'!B85 -> -202 | C7: ='Data Sheet'!C85 -> 21 | D7: ='Data Sheet'!D85 -> -28 | E7: ='Data Sheet'!E85 -> 2595 | F7: ='Data Sheet'!F85 -> -1374 | G7: ='Data Sheet'!G85 -> -695 | H7: ='Data Sheet'!H85 -> -446 | I7: ='Data Sheet'!I85 -> 111 | ... K7: ='Data Sheet'!K85 -> -3487

Sheet Customization
A1: How to use it?
A3: You can customize this workbook as you want.
B4: You can add custom formating, add conditional formating, add your own formulas… do ANYTHING.
B5: Please don't edit the "Data Sheet" only.
A7: After customization, you can upload this back on Screener.
B8: Upload on: | C8: https://www.screener.in/excel/
A10: Download your customized workbooks now onwards.
B11: Now whenever you will "Export to excel" from Screener, it will export your customized file.
A14: TESTING:
B15: This is a testing feature currently.
B16: You can report any formula errors on the worksheet at: support@screener.in

Sheet Data Sheet
A1: COMPANY NAME | B1: HINDUSTAN UNILEVER LTD | E1: =IF(B2<>B3, "A NEW VERSION OF THE WORKSHEET IS AVAILABLE", "")
A2: LATEST VERSION | B2: 2.1 | E2: PLEASE DO NOT MAKE ANY CHANGES TO THIS SHEET
A3: CURRENT VERSION | B3: 2.1
A5: META
A6: Number of shares | B6: =IF(B9>0, B9/B8, 0) -> 234.95913
A7: Face Value | B7: 1
A8: Current Price | B8: 1939.85
A9: Market Capitalization | B9: 455785.47
A15: PROFIT & LOSS
A16: Report Date | B16: 42825 | C16: 43190 | D16: 43555 | E16: 43921 | F16: 44286 | G16: 44651 | H16: 45016 | I16: 45382 | J16: 45747 | K16: 46112
A17: Sales | B17: 33162 | C17: 35545 | D17: 39310 | E17: 39783 | F17: 47028 | G17: 52446 | H17: 60580 | I17: 61896 | J17: 61328 | K17: 64468
A18: Raw Material Cost | B18: 13606 | C18: 14233 | D18: 15845 | E18: 15697 | F18: 20141 | G18: 22871 | H18: 28427 | I18: 26822 | J18: 26602 | K18: 29158
A19: Change in Inventory | B19: -144 | C19: 72 | D19: -12 | E19: 108 | F19: 405 | G19: 22 | H19: 75 | I19: 11 | J19: 125 | K19: 429
A20: Power and Fuel | B20: 295 | C20: 295 | D20: 308 | E20: 299 | F20: 339 | G20: 318 | H20: 384 | I20: 446 | J20: 403 | K20: 426
A21: Other Mfr. Exp | B21: 2887 | C21: 2998 | D21: 3041 | E21: 2906 | F21: 2868 | G21: 3354 | H21: 3791 | I21: 3385 | J21: 3687 | K21: 3304
A22: Employee Cost | B22: 1743 | C22: 1860 | D22: 1875 | E22: 1820 | F22: 2358 | G22: 2545 | H22: 2854 | I22: 3009 | J22: 2952 | K22: 3175
A23: Selling and admin | B23: 6689 | C23: 7252 | D23: 7796 | E23: 7620 | F23: 7906 | G23: 8164 | H23: 8785 | I23: 10780 | J23: 10145 | K23: 10744
A24: Other Expenses | B24: 1470 | C24: 1480 | D24: 1553 | E24: 1688 | F24: 2195 | G24: 2359 | H24: 2267 | I24: 2806 | J24: 2966 | K24: 3051
A25: Other Income | B25: 606 | C25: 353 | D25: 322 | E25: 424 | F25: 170 | G25: 219 | H25: 448 | I25: 817 | J25: 1355 | K25: 4923
A26: Depreciation | B26: 432 | C26: 520 | D26: 565 | E26: 1002 | F26: 1074 | G26: 1091 | H26: 1137 | I26: 1216 | J26: 1253 | K26: 1333
A27: Interest | B27: 35 | C27: 26 | D27: 33 | E27: 118 | F27: 117 | G27: 106 | H27: 114 | I27: 334 | J27: 381 | K27: 410
... A31: Dividend Amount | B31: 3672 | C31: 4320 | D31: 4752 | E31: 5400 | F31: 9517.5 | G31: 7990 | H31: 9165 | I31: 9870 | J31: 12455 | K31: 9635
A40: Quarters
A41: Report Date | B41: 45382 | C41: 45473 | D41: 45565 | E41: 45657 | F41: 45747 | G41: 45838 | H41: 45930 | I41: 46022 | J41: 46112 | K41: 46203
A42: Sales | B42: 15210 | C42: 15707 | D42: 15926 | E42: 15556 | F42: 15190 | G42: 15757 | H42: 15919 | I42: 16441 | J42: 16351 | K42: 17341
A43: Expenses | B43: 11675 | C43: 11965 | D43: 12139 | E43: 11867 | F43: 11572 | G43: 12118 | H43: 12137 | I43: 12660 | J43: 12514 | K43: 13394
A44: Other Income | B44: 309 | C44: 209 | D44: 203 | E44: 733 | F44: 149 | G44: 103 | H44: 269 | I44: 4048 | J44: 503 | K44: 113
A45: Depreciation | B45: 320 | C45: 329 | D45: 338 | E45: 318 | F45: 318 | G45: 326 | H45: 322 | I45: 337 | J45: 348 | K45: 353
A46: Interest | B46: 105 | C46: 93 | D46: 110 | E46: 109 | F46: 77 | G46: 122 | H46: 124 | I46: 88 | J46: 76 | K46: 75
A47: Profit before tax | B47: 3419 | C47: 3529 | D47: 3542 | E47: 3995 | F47: 3372 | G47: 3294 | H47: 3605 | I47: 7404 | J47: 3916 | K47: 3632
A48: Tax | B48: 858 | C48: 917 | D48: 947 | E48: 1006 | F48: 897 | G48: 526 | H48: 911 | I48: 801 | J48: 922 | K48: 952
A49: Net profit | B49: 2558 | C49: 2610 | D49: 2591 | E49: 2984 | F49: 2464 | G49: 2756 | H49: 2685 | I49: 6607 | J49: 2992 | K49: 2673
A50: Operating Profit | B50: 3535 | C50: 3742 | D50: 3787 | E50: 3689 | F50: 3618 | G50: 3639 | H50: 3782 | I50: 3781 | J50: 3837 | K50: 3947
A55: BALANCE SHEET
A56: Report Date | B56: 42825 | C56: 43190 | D56: 43555 | E56: 43921 | F56: 44286 | G56: 44651 | H56: 45016 | I56: 45382 | J56: 45747 | K56: 46112
A57: Equity Share Capital | B57: 216 | C57: 216 | D57: 216 | E57: 216 | F57: 235 | G57: 235 | H57: 235 | I57: 235 | J57: 235 | K57: 235
A58: Reserves | B58: 6528 | C58: 7065 | D58: 7651 | E58: 8013 | F58: 47439 | G58: 48826 | H58: 50069 | I58: 50983 | J58: 49167 | K58: 48504
A59: Borrowings | B59: 277 | D59: 99 | G59: 1043 | H59: 1219 | I59: 1484 | J59: 1648 | K59: 1478
A60: Other Liabilities | B60: 8685 | C60: 10581 | D60: 10663 | E60: 11924 | F60: 21066 | G60: 20402 | H60: 21554 | I60: 25787 | J60: 28813 | K60: 29521
A61: Total | B61: 15706 | C61: 17862 | D61: 18629 | E61: 20153 | F61: 68740 | G61: 70506 | H61: 73077 | I61: 78489 | J61: 79863 | K61: 79738
...

Sheet Histarical 
B1: ="Histarical Actuals-"&'Data Sheet'!B1 -> Histarical Actuals-HINDUSTAN UNILEVER LTD
B3: Quter Time Period | C3: ='Data Sheet'!B41 -> 45382 | D3: ='Data Sheet'!C41 -> 45473 | E3: ='Data Sheet'!D41 -> 45565 | F3: ='Data Sheet'!E41 -> 45657 | G3: ='Data Sheet'!F41 -> 45747 | H3: ='Data Sheet'!G41 -> 45838
B4: Revenu | C4: ='Data Sheet'!B42 -> 15210 | D4: ='Data Sheet'!C42 -> 15707 | E4: ='Data Sheet'!D42 -> 15926 | F4: ='Data Sheet'!E42 -> 15556 | G4: ='Data Sheet'!F42 -> 15190 | H4: ='Data Sheet'!G42 -> 15757
B5: Revenu Grwoth | C5: - | D5: =D4/C4-1 -> 0.032675871 | E5: =E4/D4-1 -> 0.013942828 | F5: =F4/E4-1 -> -0.02323245 | G5: =G4/F4-1 -> -0.023527899 | H5: =H4/G4-1 -> 0.037327189
B7: Expenses | C7: ='Data Sheet'!B43 -> 11675 | D7: ='Data Sheet'!C43 -> 11965 | E7: ='Data Sheet'!D43 -> 12139 | F7: ='Data Sheet'!E43 -> 11867 | G7: ='Data Sheet'!F43 -> 11572 | H7: ='Data Sheet'!G43 -> 12118
B8: Expenses % Sales | C8: =C7/C4 -> 0.76758711 | D8: =D7/D4 -> 0.76176227 | E8: =E7/E4 -> 0.76221273 | F8: =F7/F4 -> 0.76285678 | G8: =G7/G4 -> 0.76181698 | H8: =H7/H4 -> 0.76905502
B10: Operating Profit | C10: =C4-C7 -> 3535 | D10: =D4-D7 -> 3742 | E10: =E4-E7 -> 3787 | F10: =F4-F7 -> 3689 | G10: =G4-G7 -> 3618 | H10: =H4-H7 -> 3639
B11: Operating Margin | C11: =C10/C4 -> 0.23241289 | D11: =D10/D4 -> 0.23823773 | E11: =E10/E4 -> 0.23778727 | F11: =F10/F4 -> 0.23714322 | G11: =G10/G4 -> 0.23818302 | H11: =H10/H4 -> 0.23094498
B13: Depreciation | C13: ='Data Sheet'!B45 -> 320 | D13: ='Data Sheet'!C45 -> 329 | E13: ='Data Sheet'!D45 -> 338 | F13: ='Data Sheet'!E45 -> 318 | G13: ='Data Sheet'!F45 -> 318 | H13: ='Data Sheet'!G45 -> 326
B14: Depreciation % Sales | C14: =C13/C4 -> 0.02103879 | D14: =D13/D4 -> 0.020946075 | E14: =E13/E4 -> 0.021223157 | F14: =F13/F4 -> 0.020442273 | G14: =G13/G4 -> 0.020934826 | H14: =H13/H4 -> 0.020689217
B16: EBIT | C16: =C10-C13 -> 3215 | D16: =D10-D13 -> 3413 | E16: =E10-E13 -> 3449 | F16: =F10-F13 -> 3371 | G16: =G10-G13 -> 3300 | H16: =H10-H13 -> 3313
B17: EBIT Margin | C17: =C16/C4 -> 0.2113741 | D17: =D16/D4 -> 0.21729165 | E17: =E16/E4 -> 0.21656411 | F17: =F16/F4 -> 0.21670095 | G17: =G16/G4 -> 0.21724819 | H17: =H16/H4 -> 0.21025576
B19: Other Income | C19: ='Data Sheet'!B44 -> 309 | D19: ='Data Sheet'!C44 -> 209 | E19: ='Data Sheet'!D44 -> 203 | F19: ='Data Sheet'!E44 -> 733 | G19: ='Data Sheet'!F44 -> 149 | H19: ='Data Sheet'!G44 -> 103
B20: Other Income % Sales | C20: =C19/C4 -> 0.020315582 | D20: =D19/D4 -> 0.013306169 | E20: =E19/E4 -> 0.012746452 | F20: =F19/F4 -> 0.047120082 | G20: =G19/G4 -> 0.0098090849 | H20: =H19/H4 -> 0.0065367773
B22: Interest | C22: ='Data Sheet'!B46 -> 105 | D22: ='Data Sheet'!C46 -> 93 | E22: ='Data Sheet'!D46 -> 110 | F22: ='Data Sheet'!E46 -> 109 | G22: ='Data Sheet'!F46 -> 77 | H22: ='Data Sheet'!G46 -> 122
B23: Interest % Sales | C23: =C22/C4 -> 0.0069033531 | D23: =D22/D4 -> 0.005920927 | E23: =E22/E4 -> 0.0069069446 | F23: =F22/F4 -> 0.0070069427 | G23: =G22/G4 -> 0.0050691244 | H23: =H22/H4 -> 0.0077425906
B25: EBT | C25: =(C16+C19)-C22 -> 3419 | D25: =(D16+D19)-D22 -> 3529 | E25: =(E16+E19)-E22 -> 3542 | F25: =(F16+F19)-F22 -> 3995 | G25: =(G16+G19)-G22 -> 3372 | H25: =(H16+H19)-H22 -> 3294
B26: EBT Margin | C26: =C25/C4 -> 0.22478632 | D26: =D25/D4 -> 0.2246769 | E26: =E25/E4 -> 0.22240362 | F26: =F25/F4 -> 0.25681409 | G26: =G25/G4 -> 0.22198815 | H26: =H25/H4 -> 0.20904995
B28: Tax | C28: ='Data Sheet'!B48 -> 858 | D28: ='Data Sheet'!C48 -> 917 | E28: ='Data Sheet'!D48 -> 947 | F28: ='Data Sheet'!E48 -> 1006 | G28: ='Data Sheet'!F48 -> 897 | H28: ='Data Sheet'!G48 -> 526
B29: Tax % Sales | C29: =C28/C4 -> 0.056410256 | D29: =D28/D4 -> 0.058381613 | E29: =E28/E4 -> 0.059462514 | F29: =F28/F4 -> 0.064669581 | G29: =G28/G4 -> 0.059052008 | H29: =H28/H4 -> 0.033381989
B31: Net profit | C31: ='Data Sheet'!B49 -> 2558 | D31: ='Data Sheet'!C49 -> 2610 | E31: ='Data Sheet'!D49 -> 2591 | F31: ='Data Sheet'!E49 -> 2984 | G31: ='Data Sheet'!F49 -> 2464 | H31: ='Data Sheet'!G49 -> 2756
B32: Net profit Margin | C32: =C31/C4 -> 0.16817883 | D32: =D31/D4 -> 0.16616795 | E32: =E31/E4 -> 0.16268994 | F32: =F31/F4 -> 0.19182309 | G32: =G31/G4 -> 0.16221198 | H32: =H31/H4 -> 0.17490639

Sheet Budget_Assumptions
B1: ="Budget Assumptions-"&'Data Sheet'!B1 -> Budget Assumptions-HINDUSTAN UNILEVER LTD
B3: Budget Drive | C3: ='Histarical '!C3 -> 45382 | D3: ='Histarical '!D3 -> 45473 | E3: ='Histarical '!E3 -> 45565 | F3: ='Histarical '!F3 -> 45657 | G3: ='Histarical '!G3 -> 45747 | H3: ='Histarical '!H3 -> 45838 | I3: Average
B4: ='Histarical '!B5 -> Revenu Grwoth | C4: ='Histarical '!C5 -> - | D4: 0.032675871 | E4: 0.013942828 | F4: -0.02323245 | G4: -0.023527899 | H4: 0.037327189 | I4: =AVERAGE(D4:H4) -> 0.0074371078
B5: ='Histarical '!B8 -> Expenses % Sales | C5: 0.76758711 | D5: 0.76176227 | E5: 0.76221273 | F5: 0.76285678 | G5: 0.76181698 | H5: 0.76905502 | I5: =AVERAGE(C5:H5) -> 0.76421515
B6: ='Histarical '!B11 -> Operating Margin | C6: 0.23241289 | D6: 0.23823773 | E6: 0.23778727 | F6: 0.23714322 | G6: 0.23818302 | H6: 0.23094498 | I6: =AVERAGE(C6:H6) -> 0.23578485
B7: ='Histarical '!B14 -> Depreciation % Sales | C7: 0.02103879 | D7: 0.020946075 | E7: 0.021223157 | F7: 0.020442273 | G7: 0.020934826 | H7: 0.020689217 | I7: =AVERAGE(C7:H7) -> 0.020879056
B8: ='Histarical '!B17 -> EBIT Margin | C8: 0.2113741 | D8: 0.21729165 | E8: 0.21656411 | F8: 0.21670095 | G8: 0.21724819 | H8: 0.21025576 | I8: =AVERAGE(C8:H8) -> 0.21490579
B9: ='Histarical '!B20 -> Other Income % Sales | C9: 0.020315582 | D9: 0.013306169 | E9: 0.012746452 | F9: 0.047120082 | G9: 0.0098090849 | H9: 0.0065367773 | I9: =AVERAGE(C9:H9) -> 0.018305691
B10: ='Histarical '!B23 -> Interest % Sales | C10: 0.0069033531 | D10: 0.005920927 | E10: 0.0069069446 | F10: 0.0070069427 | G10: 0.0050691244 | H10: 0.0077425906 | I10: =AVERAGE(C10:H10) -> 0.0065916471
B11: ='Histarical '!B26 -> EBT Margin | C11: 0.22478632 | D11: 0.2246769 | E11: 0.22240362 | F11: 0.25681409 | G11: 0.22198815 | H11: 0.20904995 | I11: =AVERAGE(C11:H11) -> 0.22661984
B12: ='Histarical '!B29 -> Tax % Sales | C12: 0.056410256 | D12: 0.058381613 | E12: 0.059462514 | F12: 0.064669581 | G12: 0.059052008 | H12: 0.033381989 | I12: =AVERAGE(C12:H12) -> 0.055226327
B13: ='Histarical '!B32 -> Net profit Margin | C13: 0.16817883 | D13: 0.16616795 | E13: 0.16268994 | F13: 0.19182309 | G13: 0.16221198 | H13: 0.17490639 | I13: =AVERAGE(C13:H13) -> 0.17099636

Sheet Budgets
B1: ="Budget Next 4 Quarters-"&'Data Sheet'!B1 -> Budget Next 4 Quarters-HINDUSTAN UNILEVER LTD
B3: Quarters | C3: =Quarters[[#This Row],[Column8]] -> 45930 | D3: =Quarters[[#This Row],[Column9]] -> 46022 | E3: =Quarters[[#This Row],[Column10]] -> 46112 | F3: =Quarters[[#This Row],[Column11]] -> 46203
B5: Revenue | C5: ='Histarical '!H4*(1+Budget_Assumptions!$I$4) -> 15874.187 | D5: =C5*(1+Budget_Assumptions!$I$4) -> 15992.245 | E5: =D5*(1+Budget_Assumptions!$I$4) -> 16111.181 | F5: =E5*(1+Budget_Assumptions!$I$4) -> 16231.001
B6: Expenses | C6: =Budgets!C5*Budget_Assumptions!$I$5 -> 12131.294 | D6: =Budgets!D5*Budget_Assumptions!$I$5 -> 12221.516 | E6: =Budgets!E5*Budget_Assumptions!$I$5 -> 12312.408 | F6: =Budgets!F5*Budget_Assumptions!$I$5 -> 12403.977
B7: Operating Profit | C7: =C5-C6 -> 3742.8927 | D7: =D5-D6 -> 3770.729 | E7: =E5-E6 -> 3798.7723 | F7: =F5-F6 -> 3827.0242
B8: Depreciation | C8: =C5*Budget_Assumptions!$I$7 -> 331.43804 | D8: =D5*Budget_Assumptions!$I$7 -> 333.90298 | E8: =E5*Budget_Assumptions!$I$7 -> 336.38625 | F8: =F5*Budget_Assumptions!$I$7 -> 338.88799
B9: EBIT | C9: =C7-C8 -> 3411.4546 | D9: =D7-D8 -> 3436.826 | E9: =E7-E8 -> 3462.386 | F9: =F7-F8 -> 3488.1362
B10: Other Income | C10: =C5*Budget_Assumptions!$I$9 -> 290.58796 | D10: =D5*Budget_Assumptions!$I$9 -> 292.74909 | E10: =E5*Budget_Assumptions!$I$9 -> 294.9263 | F10: =F5*Budget_Assumptions!$I$9 -> 297.1197
B11: Interest | C11: =C5*Budget_Assumptions!$I$10 -> 104.63703 | D11: =D5*Budget_Assumptions!$I$10 -> 105.41523 | E11: =E5*Budget_Assumptions!$I$10 -> 106.19922 | F11: =F5*Budget_Assumptions!$I$10 -> 106.98903
B12: EBT | C12: =(C9+C10)-C11 -> 3597.4056 | D12: =(D9+D10)-D11 -> 3624.1599 | E12: =(E9+E10)-E11 -> 3651.1131 | F12: =(F9+F10)-F11 -> 3678.2668
B13: Tax | C13: =C5*Budget_Assumptions!$I$12 -> 876.67301 | D13: =D5*Budget_Assumptions!$I$12 -> 883.19293 | E13: =E5*Budget_Assumptions!$I$12 -> 889.76133 | F13: =F5*Budget_Assumptions!$I$12 -> 896.37858
B14: Net Profit | C14: =C12-C13 -> 2720.7326 | D14: =D12-D13 -> 2740.9669 | E14: =E12-E13 -> 2761.3518 | F14: =F12-F13 -> 2781.8883

Sheet Quarters
A1: ='Profit & Loss'!A1 -> HINDUSTAN UNILEVER LTD | E1: =UPDATE | J1: SCREENER.IN
A3: Narration | B3: ='Data Sheet'!B41 -> 45382 | C3: ='Data Sheet'!C41 -> 45473 | D3: ='Data Sheet'!D41 -> 45565 | E3: ='Data Sheet'!E41 -> 45657 | F3: ='Data Sheet'!F41 -> 45747 | G3: ='Data Sheet'!G41 -> 45838 | H3: ='Data Sheet'!H41 -> 45930 | I3: ='Data Sheet'!I41 -> 46022 | ... K3: ='Data Sheet'!K41 -> 46203
A4: Sales | B4: ='Data Sheet'!B42 -> 15210 | C4: ='Data Sheet'!C42 -> 15707 | D4: ='Data Sheet'!D42 -> 15926 | E4: ='Data Sheet'!E42 -> 15556 | F4: ='Data Sheet'!F42 -> 15190 | G4: ='Data Sheet'!G42 -> 15757 | H4: ='Data Sheet'!H42 -> 15919 | I4: ='Data Sheet'!I42 -> 16441 | ... K4: ='Data Sheet'!K42 -> 17341
A5: Expenses | B5: ='Data Sheet'!B43 -> 11675 | C5: ='Data Sheet'!C43 -> 11965 | D5: ='Data Sheet'!D43 -> 12139 | E5: ='Data Sheet'!E43 -> 11867 | F5: ='Data Sheet'!F43 -> 11572 | G5: ='Data Sheet'!G43 -> 12118 | H5: ='Data Sheet'!H43 -> 12137 | I5: ='Data Sheet'!I43 -> 12660 | ... K5: ='Data Sheet'!K43 -> 13394
A6: Operating Profit | B6: ='Data Sheet'!B50 -> 3535 | C6: ='Data Sheet'!C50 -> 3742 | D6: ='Data Sheet'!D50 -> 3787 | E6: ='Data Sheet'!E50 -> 3689 | F6: ='Data Sheet'!F50 -> 3618 | G6: ='Data Sheet'!G50 -> 3639 | H6: ='Data Sheet'!H50 -> 3782 | I6: ='Data Sheet'!I50 -> 3781 | ... K6: ='Data Sheet'!K50 -> 3947
A7: Other Income | B7: ='Data Sheet'!B44 -> 309 | C7: ='Data Sheet'!C44 -> 209 | D7: ='Data Sheet'!D44 -> 203 | E7: ='Data Sheet'!E44 -> 733 | F7: ='Data Sheet'!F44 -> 149 | G7: ='Data Sheet'!G44 -> 103 | H7: ='Data Sheet'!H44 -> 269 | I7: ='Data Sheet'!I44 -> 4048 | ... K7: ='Data Sheet'!K44 -> 113
A8: Depreciation | B8: ='Data Sheet'!B45 -> 320 | C8: ='Data Sheet'!C45 -> 329 | D8: ='Data Sheet'!D45 -> 338 | E8: ='Data Sheet'!E45 -> 318 | F8: ='Data Sheet'!F45 -> 318 | G8: ='Data Sheet'!G45 -> 326 | H8: ='Data Sheet'!H45 -> 322 | I8: ='Data Sheet'!I45 -> 337 | ... K8: ='Data Sheet'!K45 -> 353
A9: Interest | B9: ='Data Sheet'!B46 -> 105 | C9: ='Data Sheet'!C46 -> 93 | D9: ='Data Sheet'!D46 -> 110 | E9: ='Data Sheet'!E46 -> 109 | F9: ='Data Sheet'!F46 -> 77 | G9: ='Data Sheet'!G46 -> 122 | H9: ='Data Sheet'!H46 -> 124 | I9: ='Data Sheet'!I46 -> 88 | ... K9: ='Data Sheet'!K46 -> 75
A10: Profit before tax | B10: ='Data Sheet'!B47 -> 3419 | C10: ='Data Sheet'!C47 -> 3529 | D10: ='Data Sheet'!D47 -> 3542 | E10: ='Data Sheet'!E47 -> 3995 | F10: ='Data Sheet'!F47 -> 3372 | G10: ='Data Sheet'!G47 -> 3294 | H10: ='Data Sheet'!H47 -> 3605 | I10: ='Data Sheet'!I47 -> 7404 | ... K10: ='Data Sheet'!K47 -> 3632
A11: Tax | B11: ='Data Sheet'!B48 -> 858 | C11: ='Data Sheet'!C48 -> 917 | D11: ='Data Sheet'!D48 -> 947 | E11: ='Data Sheet'!E48 -> 1006 | F11: ='Data Sheet'!F48 -> 897 | G11: ='Data Sheet'!G48 -> 526 | H11: ='Data Sheet'!H48 -> 911 | I11: ='Data Sheet'!I48 -> 801 | ... K11: ='Data Sheet'!K48 -> 952
A12: Net profit | B12: ='Data Sheet'!B49 -> 2558 | C12: ='Data Sheet'!C49 -> 2610 | D12: ='Data Sheet'!D49 -> 2591 | E12: ='Data Sheet'!E49 -> 2984 | F12: ='Data Sheet'!F49 -> 2464 | G12: ='Data Sheet'!G49 -> 2756 | H12: ='Data Sheet'!H49 -> 2685 | I12: ='Data Sheet'!I49 -> 6607 | ... K12: ='Data Sheet'!K49 -> 2673
A14: OPM | B14: =IF(B4>0,B6/B4,"") -> 0.23241289 | C14: =IF(C4>0,C6/C4,"") -> 0.23823773 | D14: =IF(D4>0,D6/D4,"") -> 0.23778727 | E14: =IF(E4>0,E6/E4,"") -> 0.23714322 | F14: =IF(F4>0,F6/F4,"") -> 0.23818302 | G14: =IF(G4>0,G6/G4,"") -> 0.23094498 | H14: =IF(H4>0,H6/H4,"") -> 0.23757774 | I14: =IF(I4>0,I6/I4,"") -> 0.22997385 | ... K14: =IF(K4>0,K6/K4,"") -> 0.22761086

Sheet Revenue Analysis
B1: ="Revenue Variance Analysis-"&'Data Sheet'!B1 -> Revenue Variance Analysis-HINDUSTAN UNILEVER LTD
B2: Quarters | D2: Revenue Actuals | E2: Revenu Budeget | F2: Variance | G2: Variance % | H2: Analysis
B3: =Budgets!C3 -> 45930 | D3: =BMetricudget_VS_Actuales!C5 -> 15919 | E3: =BMetricudget_VS_Actuales!D5 -> 15874.187 | F3: =D3-E3 -> 44.813493 | G3: =(D3-E3)/E3*1 -> 0.0028230419 | H3: =IF(D3>E3,"Favorable","Unfavorable") -> Favorable
B4: =Budgets!D3 -> 46022 | D4: =BMetricudget_VS_Actuales!I5 -> 16441 | E4: =BMetricudget_VS_Actuales!J5 -> 15992.245 | F4: =D4-E4 -> 448.75546 | G4: =(D4-E4)/E4*1 -> 0.028060818 | H4: =IF(D4>E4,"Favorable","Unfavorable") -> Favorable
B5: =Budgets!E3 -> 46112 | D5: =BMetricudget_VS_Actuales!O5 -> 16351 | E5: =BMetricudget_VS_Actuales!P5 -> 16111.181 | F5: =D5-E5 -> 239.81941 | G5: =(D5-E5)/E5*1 -> 0.014885279 | H5: =IF(D5>E5,"Favorable","Unfavorable") -> Favorable
B6: =Budgets!F3 -> 46203 | D6: =BMetricudget_VS_Actuales!U5 -> 17341 | E6: =BMetricudget_VS_Actuales!V5 -> 16231.001 | F6: =D6-E6 -> 1109.9988 | G6: =(D6-E6)/E6*1 -> 0.068387576 | H6: =IF(D6>E6,"Favorable","Unfavorable") -> Favorable
B8: FP&A Revenue Commentary
B10: Sep-25: Revenue was 0.28% above budget — marginal favorable variance.
B11: Dec-25: Revenue was 2.81% above budget — stronger performance.
B12: Mar-26: Revenue was 1.49% above budget — remained above plan.
B13: Jun-26: Revenue was 6.84% above budget — largest positive revenue variance.

Sheet Cost Analysis
B1: ="Cost/Expenses Variance Analysis-"&'Data Sheet'!B1 -> Cost/Expenses Variance Analysis-HINDUSTAN UNILEVER LTD
B3: Quarters | D3: Expenses Actual | E3: Expense Budget | F3: Variance | G3: Variance % | H3: Analysis
B4: ='Revenue Analysis'!B3 -> 45930 | D4: =BMetricudget_VS_Actuales!C6 -> 12137 | E4: =BMetricudget_VS_Actuales!D6 -> 12131.294 | F4: =D4-E4 -> 5.70617 | G4: =(D4-E4)/E4*1 -> 0.0004703678 | H4: =IF(D4<E4,"favorable","Unfavorable") -> Unfavorable
B5: ='Revenue Analysis'!B4 -> 46022 | D5: =BMetricudget_VS_Actuales!O6 -> 12514 | E5: =BMetricudget_VS_Actuales!J6 -> 12221.516 | F5: =D5-E5 -> 292.48443 | G5: =(D5-E5)/E5*1 -> 0.023931928 | H5: =IF(D5<E5,"favorable","Unfavorable") -> Unfavorable
B6: ='Revenue Analysis'!B5 -> 46112 | D6: =BMetricudget_VS_Actuales!U6 -> 13394 | E6: =BMetricudget_VS_Actuales!P6 -> 12312.408 | F6: =D6-E6 -> 1081.5917 | G6: =(D6-E6)/E6*1 -> 0.087845666 | H6: =IF(D6<E6,"favorable","Unfavorable") -> Unfavorable
B7: ='Revenue Analysis'!B6 -> 46203 | D7: =BMetricudget_VS_Actuales!U6 -> 13394 | E7: =BMetricudget_VS_Actuales!V6 -> 12403.977 | F7: =D7-E7 -> 990.02299 | G7: =(D7-E7)/E7*1 -> 0.079814965 | H7: =IF(D7<E7,"favorable","Unfavorable") -> Unfavorable
B9: FP&A observation
B11: Sep-25: Expenses almost exactly on budget → only 0.05% unfavorable.
B12: Dec-25: Expenses exceeded budget by 3.59%.
B13: Mar-26: Variance reduced to 1.64%.
B14: Jun-26: Highest unfavorable expense variance at 7.98%.
B15: Jun-26 lo Revenue +6.84%, but Expenses +7.98% → expenses grew faster than revenue, creating potential margin pressure.

Sheet Operating ProfitAnalysis
B1: ="Operating Profit Variance Analysis-"&'Data Sheet'!B1 -> Operating Profit Variance Analysis-HINDUSTAN UNILEVER LTD
B3: Quarters | D3: Operating Profit Actual | E3: Operating Profit Budget | F3: Variance | G3: Variance % | H3: Analysis
B4: ='Revenue Analysis'!B3 -> 45930 | D4: =BMetricudget_VS_Actuales!C7 -> 3782 | E4: =BMetricudget_VS_Actuales!D7 -> 3742.8927 | F4: =D4-E4 -> 39.107323 | G4: =(D4-E4)/E4*1 -> 0.010448422 | H4: =IF(D4>E4,"favorable","Unfavorable") -> favorable
B5: ='Revenue Analysis'!B4 -> 46022 | D5: =BMetricudget_VS_Actuales!I7 -> 3781 | E5: =BMetricudget_VS_Actuales!J7 -> 3770.729 | F5: =D5-E5 -> 10.271027 | G5: =(D5-E5)/E5*1 -> 0.0027238836 | H5: =IF(D5>E5,"favorable","Unfavorable") -> favorable
B6: ='Revenue Analysis'!B5 -> 46112 | D6: =BMetricudget_VS_Actuales!O7 -> 3837 | E6: =BMetricudget_VS_Actuales!P7 -> 3798.7723 | F6: =D6-E6 -> 38.227709 | G6: =(D6-E6)/E6*1 -> 0.010063175 | H6: =IF(D6>E6,"favorable","Unfavorable") -> favorable
B7: ='Revenue Analysis'!B6 -> 46203 | D7: =BMetricudget_VS_Actuales!U7 -> 3947 | E7: =BMetricudget_VS_Actuales!V7 -> 3827.0242 | F7: =D7-E7 -> 119.97583 | G7: =(D7-E7)/E7*1 -> 0.03134964 | H7: =IF(D7>E7,"favorable","Unfavorable") -> favorable
B9: Sep-25: Operating Profit +1.04% above budget.
B10: Dec-25: +0.27% — almost on budget.
B11: Mar-26: +1.01% — performance improved.
B12: Jun-26: +3.13% — highest favorable variance.

Sheet EBIT Analysis
B1: ="EBIT Variance Analysis-"&'Data Sheet'!B1 -> EBIT Variance Analysis-HINDUSTAN UNILEVER LTD
B3: Quarters | D3: EBIT Actual | E3: EBIT Budget | F3: Variance | G3: Variance % | H3: Analysis
B4: ='Revenue Analysis'!B3 -> 45930 | D4: =BMetricudget_VS_Actuales!C9 -> 3460 | E4: =BMetricudget_VS_Actuales!D9 -> 3411.4546 | F4: =D4-E4 -> 48.545359 | G4: =(D4-E4)/E4*1 -> 0.014230105 | H4: =IF(D4>E4,"Favorable","UnFavorable") -> Favorable
B5: ='Revenue Analysis'!B4 -> 46022 | D5: =BMetricudget_VS_Actuales!I9 -> 3444 | E5: =BMetricudget_VS_Actuales!J9 -> 3436.826 | F5: =D5-E5 -> 7.1740027 | G5: =(D5-E5)/E5*1 -> 0.0020873919 | H5: =IF(D5>E5,"Favorable","UnFavorable") -> Favorable
B6: ='Revenue Analysis'!B5 -> 46112 | D6: =BMetricudget_VS_Actuales!O9 -> 3489 | E6: =BMetricudget_VS_Actuales!P9 -> 3462.386 | F6: =D6-E6 -> 26.613957 | G6: =(D6-E6)/E6*1 -> 0.0076865945 | H6: =IF(D6>E6,"Favorable","UnFavorable") -> Favorable
B7: ='Revenue Analysis'!B6 -> 46203 | D7: =BMetricudget_VS_Actuales!U9 -> 3594 | E7: =BMetricudget_VS_Actuales!V9 -> 3488.1362 | F7: =D7-E7 -> 105.86382 | G7: =(D7-E7)/E7*1 -> 0.030349681 | H7: =IF(D7>E7,"Favorable","UnFavorable") -> Favorable
B9: FP&A observation
B11: Sep-25: EBIT +1.42% above budget.
B12: Dec-25: +0.21% — almost on budget.
B13: Mar-26: +0.77%.
B14: Jun-26: +3.03% — highest favorable variance.

Sheet Other Income
B1: ="Other Income Variance Analysis-"&'Data Sheet'!B1 -> Other Income Variance Analysis-HINDUSTAN UNILEVER LTD
B3: Quarters | D3: Other Income Actual | E3: Other income Budget | F3: Variance | G3: Variance % | H3: Analysis
B4: ='Revenue Analysis'!B3 -> 45930 | D4: =BMetricudget_VS_Actuales!C10 -> 269 | E4: =BMetricudget_VS_Actuales!D10 -> 290.58796 | F4: =D4-E4 -> -21.587958 | G4: =(D4-E4)/E4*1 -> -0.074290615 | H4: =IF(D4>E4,"Favorable","Unfavorable") -> Unfavorable
B5: ='Revenue Analysis'!B4 -> 46022 | D5: =BMetricudget_VS_Actuales!I10 -> 4048 | E5: =BMetricudget_VS_Actuales!J10 -> 292.74909 | F5: =D5-E5 -> 3755.2509 | G5: =(D5-E5)/E5*1 -> 12.827541 | H5: =IF(D5>E5,"Favorable","Unfavorable") -> Favorable
B6: ='Revenue Analysis'!B5 -> 46112 | D6: =BMetricudget_VS_Actuales!O10 -> 503 | E6: =BMetricudget_VS_Actuales!P10 -> 294.9263 | F6: =D6-E6 -> 208.0737 | G6: =(D6-E6)/E6*1 -> 0.70551084 | H6: =IF(D6>E6,"Favorable","Unfavorable") -> Favorable
B7: ='Revenue Analysis'!B6 -> 46203 | D7: =BMetricudget_VS_Actuales!U10 -> 113 | E7: =BMetricudget_VS_Actuales!V10 -> 297.1197 | F7: =D7-E7 -> -184.1197 | G7: =(D7-E7)/E7*1 -> -0.6196819 | H7: =IF(D7>E7,"Favorable","Unfavorable") -> Unfavorable
B9: P&A observation
B11: Dec-25 is the major point: Other Income was ₹4,048 vs ₹292.75 budget, creating a ₹3,755.25 favorable variance (+1,282.75%).

Sheet Intrest Exp
B1: ="Interest Exp Variance Analysis-"&'Data Sheet'!B1 -> Interest Exp Variance Analysis-HINDUSTAN UNILEVER LTD
B3: Quarters | D3: Interest Actual | E3: Interest Budget | F3: Variance | G3: Variance % | H3: Analysis
B4: ='Revenue Analysis'!B3 -> 45930 | D4: =BMetricudget_VS_Actuales!C11 -> 124 | E4: =BMetricudget_VS_Actuales!D11 -> 104.63703 | F4: =D4-E4 -> 19.362965 | G4: =(D4-E4)/E4*1 -> 0.18504887 | H4: =IF(D4<E4,"Favorable","Unfavorable") -> Unfavorable
B5: ='Revenue Analysis'!B4 -> 46022 | D5: =BMetricudget_VS_Actuales!I11 -> 88 | E5: =BMetricudget_VS_Actuales!J11 -> 105.41523 | F5: =D5-E5 -> -17.415232 | G5: =(D5-E5)/E5*1 -> -0.16520603 | H5: =IF(D5<E5,"Favorable","Unfavorable") -> Favorable
B6: ='Revenue Analysis'!B5 -> 46112 | D6: =BMetricudget_VS_Actuales!O11 -> 76 | E6: =BMetricudget_VS_Actuales!P11 -> 106.19922 | F6: =D6-E6 -> -30.199216 | G6: =(D6-E6)/E6*1 -> -0.28436383 | H6: =IF(D6<E6,"Favorable","Unfavorable") -> Favorable
B7: ='Revenue Analysis'!B6 -> 46203 | D7: =BMetricudget_VS_Actuales!U11 -> 75 | E7: =BMetricudget_VS_Actuales!V11 -> 106.98903 | F7: =D7-E7 -> -31.989031 | G7: =(D7-E7)/E7*1 -> -0.29899356 | H7: =IF(D7<E7,"Favorable","Unfavorable") -> Favorable
B9: FP&A Observations – Interest Expense
B11: 1. Sep-25: Interest expense was 18.50% above budget, indicating an unfavorable variance.
B12: 2. Dec-25: Interest expense was 16.52% below budget, resulting in a favorable variance.
B13: 3. Mar-26: Interest expense was 28.44% below budget, showing continued improvement.
B14: 4. Jun-26: Interest expense was 29.90% below budget, the largest favorable variance during the four quarters.
B15: 5. Overall, interest expense was below budget in 3 out of 4 quarters, which helped support EBT performance.

Sheet EBT
B1: ="EBT Variance Analysis-"&'Data Sheet'!B1 -> EBT Variance Analysis-HINDUSTAN UNILEVER LTD
B3: Quarters | D3: EBT Actual | E3: EBT Budget | F3: Variance | G3: Variance % | H3: Analysis
B4: ='Revenue Analysis'!B3 -> 45930 | D4: =BMetricudget_VS_Actuales!C12 -> 3605 | E4: =BMetricudget_VS_Actuales!D12 -> 3597.4056 | F4: =D4-E4 -> 7.5944351 | G4: =(D4-E4)/E4*1 -> 0.0021110867 | H4: =IF(D4>E4,"Favorable","Unfavorable") -> Favorable
B5: ='Revenue Analysis'!B4 -> 46022 | D5: =BMetricudget_VS_Actuales!I12 -> 7404 | E5: =BMetricudget_VS_Actuales!J12 -> 3624.1599 | F5: =D5-E5 -> 3779.8401 | G5: =(D5-E5)/E5*1 -> 1.0429562 | H5: =IF(D5>E5,"Favorable","Unfavorable") -> Favorable
B6: ='Revenue Analysis'!B5 -> 46112 | D6: =BMetricudget_VS_Actuales!O12 -> 3916 | E6: =BMetricudget_VS_Actuales!P12 -> 3651.1131 | F6: =D6-E6 -> 264.88687 | G6: =(D6-E6)/E6*1 -> 0.072549621 | H6: =IF(D6>E6,"Favorable","Unfavorable") -> Favorable
B7: ='Revenue Analysis'!B6 -> 46203 | D7: =BMetricudget_VS_Actuales!U12 -> 3632 | E7: =BMetricudget_VS_Actuales!V12 -> 3678.2668 | F7: =D7-E7 -> -46.266847 | G7: =(D7-E7)/E7*1 -> -0.012578437 | H7: =IF(D7>E7,"Favorable","Unfavorable") -> Unfavorable
B9: EBT Observations
B11: 1. Sep-25: EBT was 0.21% above budget, a small favorable variance. Performance was almost in line with expectations.
B12: 2. Dec-25: EBT was 104.30% above budget, a very large favorable variance. This was mainly driven by the exceptionally high Other Income variance, so it should not be treated as purely operational improvement.
B13: 3. Mar-26: EBT was 7.25% above budget, showing a favorable result, supported by higher EBIT, higher Other Income and lower Interest Expense.
B14: 4. Jun-26: EBT was 1.26% below budget, an unfavorable variance. Although EBIT and Interest Expense were favorable, the lower Other Income reduced EBT.

Sheet TAX
B1: ="TAX Variance Analysis-"&'Data Sheet'!B1 -> TAX Variance Analysis-HINDUSTAN UNILEVER LTD
B3: Quarters | D3: TAX Actual | E3: TAX Budget | F3: Variance | G3: Variance % | H3: Analysis
B4: ='Revenue Analysis'!B3 -> 45930 | D4: =BMetricudget_VS_Actuales!C13 -> 911 | E4: =BMetricudget_VS_Actuales!D13 -> 876.67301 | F4: =D4-E4 -> 34.326986 | G4: =(D4-E4)/E4*1 -> 0.039155975 | H4: =IF(D4<E4,"Favorable","Unfavorable") -> Unfavorable
B5: ='Revenue Analysis'!B4 -> 46022 | D5: =BMetricudget_VS_Actuales!I13 -> 801 | E5: =BMetricudget_VS_Actuales!J13 -> 883.19293 | F5: =D5-E5 -> -82.192925 | G5: =(D5-E5)/E5*1 -> -0.093063387 | H5: =IF(D5<E5,"Favorable","Unfavorable") -> Favorable
B6: ='Revenue Analysis'!B5 -> 46112 | D6: =BMetricudget_VS_Actuales!O13 -> 922 | E6: =BMetricudget_VS_Actuales!P13 -> 889.76133 | F6: =D6-E6 -> 32.238674 | G6: =(D6-E6)/E6*1 -> 0.036232945 | H6: =IF(D6<E6,"Favorable","Unfavorable") -> Unfavorable
B7: ='Revenue Analysis'!B6 -> 46203 | D7: =BMetricudget_VS_Actuales!U13 -> 952 | E7: =BMetricudget_VS_Actuales!V13 -> 896.37858 | F7: =D7-E7 -> 55.621423 | G7: =(D7-E7)/E7*1 -> 0.062051263 | H7: =IF(D7<E7,"Favorable","Unfavorable") -> Unfavorable
B9: Final FP&A Observation
B11: Sep-25: Tax expense 3.92% above budget → Unfavorable.
B12: Dec-25: Tax expense 9.31% below budget → Favorable.
B13: Mar-26: Tax expense 3.62% above budget → Unfavorable.
B14: Jun-26: Tax expense 6.21% above budget → Unfavorable; highest unfavorable variance.
B16: Overall: Tax expense exceeded budget in 3 out of 4 quarters. Dec-25 was the only favorable quarter

Sheet Net Profit
A1: . | B1: ="NP Variance Analysis-"&'Data Sheet'!B1 -> NP Variance Analysis-HINDUSTAN UNILEVER LTD
B3: Quarters | D3: NP Actual | E3: NP Budget | F3: Variance | G3: Variance % | H3: Analysis
B4: ='Revenue Analysis'!B3 -> 45930 | D4: =BMetricudget_VS_Actuales!C14 -> 2694 | E4: =BMetricudget_VS_Actuales!D14 -> 2720.7326 | F4: =D4-E4 -> -26.732551 | G4: =(D4-E4)/E4*1 -> -0.0098254976 | H4: =IF(D4>E4,"Favorable","Unfavorable") -> Unfavorable
B5: ='Revenue Analysis'!B4 -> 46022 | D5: =BMetricudget_VS_Actuales!I14 -> 6603 | E5: =BMetricudget_VS_Actuales!J14 -> 2740.9669 | F5: =D5-E5 -> 3862.0331 | G5: =(D5-E5)/E5*1 -> 1.4090039 | H5: =IF(D5>E5,"Favorable","Unfavorable") -> Favorable
B6: ='Revenue Analysis'!B5 -> 46112 | D6: =BMetricudget_VS_Actuales!O14 -> 2994 | E6: =BMetricudget_VS_Actuales!P14 -> 2761.3518 | F6: =D6-E6 -> 232.6482 | G6: =(D6-E6)/E6*1 -> 0.084251562 | H6: =IF(D6>E6,"Favorable","Unfavorable") -> Favorable
B7: ='Revenue Analysis'!B6 -> 46203 | D7: =BMetricudget_VS_Actuales!U14 -> 2680 | E7: =BMetricudget_VS_Actuales!V14 -> 2781.8883 | F7: =D7-E7 -> -101.88827 | G7: =(D7-E7)/E7*1 -> -0.036625579 | H7: =IF(D7>E7,"Favorable","Unfavorable") -> Unfavorable
B8: NP Observations
B10: 1. Sep-25: NP was 0.98% below budget → Unfavorable. Small negative variance.
B11: 2. Dec-25: NP was 140.90% above budget → Favorable. The major driver was the exceptionally high Other Income, so this should not be considered purely core operating performance.
B12: 3. Mar-26: NP was 8.43% above budget → Favorable, supported by higher EBT despite slightly higher tax expense.
B13: 4. Jun-26: NP was 3.66% below budget → Unfavorable. Lower Other Income and higher tax expense offset the favorable EBIT and interest-expense performance.

Sheet Executive Summary 
B2: Executive Summary – HUL FP&A Variance Analysis
B4: KPI | C4: Key Finding | D4: FP&A Interpretation
B5: Revenue | C5: Above budget in all 4 quarters | D5: Revenue performance was consistently favorable
B6: Expenses | C6: Above budget in all 4 quarters | D6: Cost control needs attention, especially Jun-26
B7: Operating Profit | C7: Above budget in all 4 quarters | D7: Operating performance remained favorable
B8: EBIT | C8: Above budget in all 4 quarters | D8: Core operating profitability was above plan
B9: Other Income | C9: Highly volatile | D9: Significant impact on EBT and NP
B10: Interest Expense | C10: Below budget in 3 of 4 quarters | D10: Financing cost was generally favorable
B11: EBT | C11: Above budget in 3 of 4 quarters | D11: Strong overall, but influenced by Other Income
B12: Tax | C12: Above budget in 3 of 4 quarters | D12: Tax variance requires monitoring
B13: Net Profit | C13: Above budget in 2 of 4 quarters | D13: Profitability was mixed across quarters
B15: 2. Key Management Insights
B17: Insight 1 – Revenue:
B18: Revenue remained above budget across all four quarters. Jun-26 recorded the highest favorable variance at +6.84%.
B20: Insight 2 – Cost:
B21: Expenses were above budget in every quarter. Jun-26 had the highest unfavorable variance of +7.98%, which was higher than the revenue variance of +6.84%.
B23: Insight 3 – Operating Profit:
B24: Operating Profit and EBIT were above budget in all four quarters, indicating favorable core operating performance.
B26: Insight 4 – Other Income:
B27: Other Income showed significant volatility, particularly Dec-25 (+1,282.75%). This had a major impact on EBT and Net Profit.
B29: Insight 5 – Financing Cost:
B30: Interest expense was below budget in Dec-25, Mar-26 and Jun-26, providing a favorable impact on profitability.
B32: Insight 6 – Net Profit:
... B42: Track Revenue → Operating Profit → EBIT → EBT → Net Profit as a complete profitability chain.

Sheet BMetricudget_VS_Actuales
B1: ="Actual vs Budget Variance Analysis-"&'Data Sheet'!B1 -> Actual vs Budget Variance Analysis-HINDUSTAN UNILEVER LTD
B3: Quarter 1 - Sep25 | H3: Quarter 2 - Dec25 | N3: Quarter 3 - Mar26 | T3: Quarter 4 - Jun26
C4: Actual | D4: Budget | E4: Variance | F4: Variance% | I4: Actual | J4: Budget | K4: Variance | L4: Variance% | O4: Actual | P4: Budget | Q4: Variance | R4: Variance% | U4: Actual | V4: Budget | W4: Variance | X4: Variance%
B5: Revenue | C5: =Quarters!H4 -> 15919 | D5: =Budgets!C5 -> 15874.187 | E5: =C5-D5 -> 44.813493 | F5: =(C5-D5)/D5*1 -> 0.0028230419 | H5: Revenue | I5: =Quarters!I4 -> 16441 | J5: =Budgets!D5 -> 15992.245 | K5: =I5-J5 -> 448.75546 | L5: =(I5-J5)/J5*1 -> 0.028060818 | N5: Revenue | O5: =Quarters!J4 -> 16351 | P5: =Budgets!E5 -> 16111.181 | Q5: =O5-P5 -> 239.81941 | R5: =(O5-P5)/P5*1 -> 0.014885279 | T5: Revenue | U5: =Quarters!K4 -> 17341 | V5: =Budgets!F5 -> 16231.001 | W5: =U5-V5 -> 1109.9988 | X5: =(U5-V5)/V5*1 -> 0.068387576
B6: Expenses | C6: =Quarters!H5 -> 12137 | D6: =Budgets!C6 -> 12131.294 | E6: =C6-D6 -> 5.70617 | F6: =(C6-D6)/D6*1 -> 0.0004703678 | H6: Expenses | I6: =Quarters!I5 -> 12660 | J6: =Budgets!D6 -> 12221.516 | K6: =I6-J6 -> 438.48443 | L6: =(I6-J6)/J6*1 -> 0.035878073 | N6: Expenses | O6: =Quarters!J5 -> 12514 | P6: =Budgets!E6 -> 12312.408 | Q6: =O6-P6 -> 201.5917 | R6: =(O6-P6)/P6*1 -> 0.016373052 | T6: Expenses | U6: =Quarters!K5 -> 13394 | V6: =Budgets!F6 -> 12403.977 | W6: =U6-V6 -> 990.02299 | X6: =(U6-V6)/V6*1 -> 0.079814965
B7: Operating Profit | C7: =C5-C6 -> 3782 | D7: =Budgets!C7 -> 3742.8927 | E7: =C7-D7 -> 39.107323 | F7: =(C7-D7)/D7*1 -> 0.010448422 | H7: Operating Profit | I7: =I5-I6 -> 3781 | J7: =Budgets!D7 -> 3770.729 | K7: =I7-J7 -> 10.271027 | L7: =(I7-J7)/J7*1 -> 0.0027238836 | N7: Operating Profit | O7: =O5-O6 -> 3837 | P7: =Budgets!E7 -> 3798.7723 | Q7: =O7-P7 -> 38.227709 | R7: =(O7-P7)/P7*1 -> 0.010063175 | T7: Operating Profit | U7: =U5-U6 -> 3947 | V7: =Budgets!F7 -> 3827.0242 | W7: =U7-V7 -> 119.97583 | X7: =(U7-V7)/V7*1 -> 0.03134964
B8: Depreciation | C8: =Quarters[[#This Row],[Column8]] -> 322 | D8: =Budgets!C8 -> 331.43804 | E8: =C8-D8 -> -9.4380356 | F8: =(C8-D8)/D8*1 -> -0.028476018 | H8: Depreciation | I8: =Quarters!I8 -> 337 | J8: =Budgets!D8 -> 333.90298 | K8: =I8-J8 -> 3.097024 | L8: =(I8-J8)/J8*1 -> 0.0092752213 | N8: Depreciation | O8: =Quarters!J8 -> 348 | P8: =Budgets!E8 -> 336.38625 | Q8: =O8-P8 -> 11.613752 | R8: =(O8-P8)/P8*1 -> 0.034525049 | T8: Depreciation | U8: =Quarters[[#This Row],[Column11]] -> 353 | V8: =Budgets!F8 -> 338.88799 | W8: =U8-V8 -> 14.112011 | X8: =(U8-V8)/V8*1 -> 0.04164211
B9: EBIT | C9: =C7-C8 -> 3460 | D9: =Budgets!C9 -> 3411.4546 | E9: =C9-D9 -> 48.545359 | F9: =(C9-D9)/D9*1 -> 0.014230105 | H9: EBIT | I9: =I7-I8 -> 3444 | J9: =Budgets!D9 -> 3436.826 | K9: =I9-J9 -> 7.1740027 | L9: =(I9-J9)/J9*1 -> 0.0020873919 | N9: EBIT | O9: =O7-O8 -> 3489 | P9: =Budgets!E9 -> 3462.386 | Q9: =O9-P9 -> 26.613957 | R9: =(O9-P9)/P9*1 -> 0.0076865945 | T9: EBIT | U9: =U7-U8 -> 3594 | V9: =Budgets!F9 -> 3488.1362 | W9: =U9-V9 -> 105.86382 | X9: =(U9-V9)/V9*1 -> 0.030349681
B10: Other Income | C10: =Quarters!H7 -> 269 | D10: =Budgets!C10 -> 290.58796 | E10: =C10-D10 -> -21.587958 | F10: =(C10-D10)/D10*1 -> -0.074290615 | H10: Other Income | I10: =Quarters!I7 -> 4048 | J10: =Budgets!D10 -> 292.74909 | K10: =I10-J10 -> 3755.2509 | L10: =(I10-J10)/J10*1 -> 12.827541 | N10: Other Income | O10: =Quarters!J7 -> 503 | P10: =Budgets!E10 -> 294.9263 | Q10: =O10-P10 -> 208.0737 | R10: =(O10-P10)/P10*1 -> 0.70551084 | T10: Other Income | U10: =Quarters!K7 -> 113 | V10: =Budgets!F10 -> 297.1197 | W10: =U10-V10 -> -184.1197 | X10: =(U10-V10)/V10*1 -> -0.6196819
B11: Interest | C11: =Quarters!H9 -> 124 | D11: =Budgets!C11 -> 104.63703 | E11: =C11-D11 -> 19.362965 | F11: =(C11-D11)/D11*1 -> 0.18504887 | H11: Interest | I11: =Quarters!I9 -> 88 | J11: =Budgets!D11 -> 105.41523 | K11: =I11-J11 -> -17.415232 | L11: =(I11-J11)/J11*1 -> -0.16520603 | N11: Interest | O11: =Quarters!J9 -> 76 | P11: =Budgets!E11 -> 106.19922 | Q11: =O11-P11 -> -30.199216 | R11: =(O11-P11)/P11*1 -> -0.28436383 | T11: Interest | U11: =Quarters!K9 -> 75 | V11: =Budgets!F11 -> 106.98903 | W11: =U11-V11 -> -31.989031 | X11: =(U11-V11)/V11*1 -> -0.29899356
B12: EBT | C12: =(C9+C10)-C11 -> 3605 | D12: =Budgets!C12 -> 3597.4056 | E12: =C12-D12 -> 7.5944351 | F12: =(C12-D12)/D12*1 -> 0.0021110867 | H12: EBT | I12: =(I9+I10)-I11 -> 7404 | J12: =Budgets!D12 -> 3624.1599 | K12: =I12-J12 -> 3779.8401 | L12: =(I12-J12)/J12*1 -> 1.0429562 | N12: EBT | O12: =(O9+O10)-O11 -> 3916 | P12: =Budgets!E12 -> 3651.1131 | Q12: =O12-P12 -> 264.88687 | R12: =(O12-P12)/P12*1 -> 0.072549621 | T12: EBT | U12: =(U9+U10)-U11 -> 3632 | V12: =Budgets!F12 -> 3678.2668 | W12: =U12-V12 -> -46.266847 | X12: =(U12-V12)/V12*1 -> -0.012578437
B13: Tax | C13: =Quarters!H11 -> 911 | D13: =Budgets!C13 -> 876.67301 | E13: =C13-D13 -> 34.326986 | F13: =(C13-D13)/D13*1 -> 0.039155975 | H13: Tax | I13: =Quarters!I11 -> 801 | J13: =Budgets!D13 -> 883.19293 | K13: =I13-J13 -> -82.192925 | L13: =(I13-J13)/J13*1 -> -0.093063387 | N13: Tax | O13: =Quarters!J11 -> 922 | P13: =Budgets!E13 -> 889.76133 | Q13: =O13-P13 -> 32.238674 | R13: =(O13-P13)/P13*1 -> 0.036232945 | T13: Tax | U13: =Quarters!K11 -> 952 | V13: =Budgets!F13 -> 896.37858 | W13: =U13-V13 -> 55.621423 | X13: =(U13-V13)/V13*1 -> 0.062051263
B14: Net Profit | C14: =C12-C13 -> 2694 | D14: =Budgets!C14 -> 2720.7326 | E14: =C14-D14 -> -26.732551 | F14: =(C14-D14)/D14*1 -> -0.0098254976 | H14: Net Profit | I14: =I12-I13 -> 6603 | J14: =Budgets!D14 -> 2740.9669 | K14: =I14-J14 -> 3862.0331 | L14: =(I14-J14)/J14*1 -> 1.4090039 | N14: Net Profit | O14: =O12-O13 -> 2994 | P14: =Budgets!E14 -> 2761.3518 | Q14: =O14-P14 -> 232.6482 | R14: =(O14-P14)/P14*1 -> 0.084251562 | T14: Net Profit | U14: =U12-U13 -> 2680 | V14: =Budgets!F14 -> 2781.8883 | W14: =U14-V14 -> -101.88827 | X14: =(U14-V14)/V14*1 -> -0.036625579

Sheet Rolling Forecasting
B10: Period No | C10: Years | D10: Sales | E10: Sales Growth | F10: Expenses | G10: Expenses Growth | H10: OP | I10: OP Growth | J10: Depreciation | K10: Depreciation Growth | L10: EBIT | M10: EBIT Growth | N10: Other Income | O10: Other Income Growth | P10: Interest | Q10: Interest Growth | R10: EBT | S10: EBT Growth | T10: TAX | U10: TAX Growth | V10: Net Profit | W10: Net Profit Growth
B11: 1 | C11: Sep-25A | D11: 15919 | E11: - | F11: 12137 | G11: - | H11: 3782 | I11: - | J11: 322 | K11: - | L11: 3460 | M11: - | N11: 269 | O11: - | P11: 124 | Q11: - | R11: 3605 | S11: - | T11: 911 | U11: - | V11: 2694 | W11: -
B12: 2 | C12: Dec-25A | D12: 16441 | E12: 0.032791004 | F12: 12660 | G12: 0.043091373 | H12: 3781 | I12: -0.00026441036 | J12: 337 | K12: 0.046583851 | L12: 3444 | M12: -0.0046242775 | N12: 4048 | O12: 14.048327 | P12: 88 | Q12: -0.29032258 | R12: 7404 | S12: 1.0538141 | T12: 801 | U12: -0.12074643 | V12: 6603 | W12: 1.4510022
B13: 3 | C13: Mar-26A | D13: 16351 | E13: -0.0054741196 | F13: 12514 | G13: -0.011532385 | H13: 3837 | I13: 0.014810897 | J13: 348 | K13: 0.03264095 | L13: 3489 | M13: 0.013066202 | N13: 503 | O13: -0.87574111 | P13: 76 | Q13: -0.13636364 | R13: 3916 | S13: -0.4710967 | T13: 922 | U13: 0.15106117 | V13: 2994 | W13: -0.54656974
B14: 4 | C14: Jun-26A | D14: 17341 | E14: 0.060546756 | F14: 13394 | G14: 0.07032124 | H14: 3947 | I14: 0.02866823 | J14: 353 | K14: 0.014367816 | L14: 3594 | M14: 0.030094583 | N14: 113 | O14: -0.77534791 | P14: 75 | Q14: -0.013157895 | R14: 3632 | S14: -0.072522983 | T14: 952 | U14: 0.032537961 | V14: 2680 | W14: -0.10487642
